Workbook

Sheet Case_Data
A1: Case data (as given in the case)
A2: Item | B2: Unit | C2: Maize | D2: Vegetable | E2: Source
A3: Number of FPOs | C3: 7 | D3: 5 | E3: Case background: 12 FPOs, 7 maize, 5 vegetables
A4: Members per typical FPO | C4: 500 | D4: 500 | E4: Case background
A5: Women share of members | C5: 0.2 | D5: 0.2 | E5: Case background
A6: Annual turnover, low end | B6: Rs lakh | C6: 20 | D6: 20 | E6: Case background: Rs 20 to 35 lakh
A7: Annual turnover, high end | B7: Rs lakh | C7: 35 | D7: 35 | E7: Case background
A8: Annual turnover, midpoint | B8: Rs lakh | C8: =(C6+C7)/2 -> 27.5 | D8: =(D6+D7)/2 -> 27.5
A9: Share capital per member | B9: Rs | C9: 2000 | D9: 2000 | E9: Case background
A10: Share capital per FPO | B10: Rs lakh | C10: =C4*C9/100000 -> 10 | D10: =D4*D9/100000 -> 10 | E10: Equals the Rs 10 lakh working capital in the case: the FPO is running on its share capital alone
A11: Working capital available | B11: Rs lakh | C11: 10 | D11: 10 | E11: Key challenges: financial access
A12: Peak-season working capital need | B12: Rs lakh | C12: 25 | D12: 25 | E12: Key challenges: financial access
A13: Working capital gap per FPO | B13: Rs lakh | C13: =C12-C11 -> 15 | D13: =D12-D11 -> 15
A14: Board size / women directors | C14: 9 | D14: 1 | E14: Case: nine-member board with one woman director (C = board, D = women)
A15: Foundation commitment per year | B15: USD m | C15: 1 | E15: Case background: US$1 million a year for 3 to 5 years

Sheet Assumptions
A1: Assumptions (blue = typed input; every row has a reason and source code, see Targets sheet for the source list)
A2: Assumption | B2: Unit | C2: Maize | D2: Vegetable | E2: Reason / source
A3: General
A4: Exchange rate | B4: Rs/USD | C4: 95 | E4: [S13] Rupee at 94.8 to 95.95 per USD in Aug to Sep 2026; 95 used
A5: Programme years planned | C5: 5 | E5: Case allows 3 to 5; we plan 5 with a go/no-go checkpoint at end of Year 2
A6: Year 5 membership and participation (per FPO)
A7: New women members added by Year 5 | C7: 150 | D7: 150 | E7: Enrolled through JEEViKA self-help groups already active in these villages [S10]; about 30 a year
A8: Members who sell produce through the FPO | C8: 0.5 | D8: 0.45 | E8: [S9] SRIJAN raised members selling to their FPOs to 39% in 2 years; we allow 5 years plus input credit tied to sales. Vegetables lower because of daily, small lots
A9: Crop area per selling member | B9: ha | C9: 0.4 | D9: 0.2 | E9: [S11] 83% of Bihar holdings are under 1 ha. Maize is the main rabi crop in Kosi; vegetables are grown on small plots
A10: Yield per hectare per year | B10: t/ha | C10: 4.5 | D10: 22.5 | E10: [S11] Bihar maize about 4 t/ha, rabi higher. Vegetables: 15 t/ha a season x 1.5 seasons (our assumption)
A11: Share of output that is sold | C11: 0.9 | D11: 0.85 | E11: Maize is a cash crop; vegetables lose some to home use and damage [S12]
A12: Share of a selling member's output the FPO handles | C12: 0.65 | D12: 0.5 | E12: Input credit repaid in produce and assured payment in 7 days pull volume; vegetables lower because of side-selling to local markets
A13: Average farm-gate price | B13: Rs/t | C13: 22500 | D13: 14000 | E13: [S14] Maize MSP Rs 2,400/qtl but Bihar has no state maize procurement; Purnia mandi near Rs 2,100 to 2,300. Vegetables: blended Rs 14/kg (our assumption)
A14: Members buying inputs through the FPO | C14: 0.7 | D14: 0.7 | E14: [S9] SRIJAN reached 88% of shareholders buying inputs; 70% used
A15: Input spend per member per year | B15: Rs | C15: 12000 | D15: 8000 | E15: Seed, fertiliser and crop protection for 0.4 ha maize or 0.2 ha vegetables (our assumption)
A16: Share of that spend bought from the FPO | C16: 0.5 | D16: 0.5 | E16: Fertiliser licence and bulk buying; half, not all
A17: Nursery seedling sales | B17: Rs lakh | C17: 0 | D17: 5 | E17: Vegetable FPOs run a shade-net nursery (also a flood fallback: seedlings can be replanted fast)
A18: Margins the FPO keeps
A19: Margin on produce sold | C19: 0.03 | D19: 0.07 | E19: Maize: about Rs 65/qtl spread on bulk contracts. Vegetables: grading premium and lower loss [S12: 4.9% to 11.6% vegetable loss]
A20: Share of maize held in storage for later sale | C20: 0.4 | D20: 0 | E20: [S15] Small farmers sell in distress at harvest; larger farmers hold 3 to 4 months
A21: Net gain on stored maize after rent, interest and shrinkage | C21: 0.04 | D21: 0 | E21: Assumes about 9% to 10% price rise in 4 months less about 5% holding cost; e-NWR pledge loan pays for the stock [S7]
A22: Margin on inputs | C22: 0.08 | D22: 0.1 | E22: Dealer margin on bulk seed and fertiliser (our assumption)
A23: Margin on nursery sales | C23: 0 | D23: 0.3 | E23: Our assumption
A24: Drying, cleaning and storage fee | B24: Rs/t | C24: 400 | D24: 0 | E24: Rs 40/qtl charged on FPO volume and on traders' maize
A25: Third-party volume as a multiple of own volume | C25: 0.5 | D25: 0 | E25: Dryer and godown rented out to non-members in spare weeks
A26: Cold room fees from non-members | B26: Rs lakh | C26: 0 | D26: 0.6 | E26: Pay-per-crate service, as in the Ecozen/Oorja model in Muzaffarpur [S8]
A27: Blended margin today | C27: 0.05 | D27: 0.05 | E27: Small trading and input margins at current scale (our assumption)
A28: Running cost of an independent FPO (per year)
A29: CEO salary | B29: Rs lakh | C29: 3.6 | D29: 3.6 | E29: Rs 30,000 a month. Govt management cost norm is Rs 18 lakh over 3 years = Rs 6 lakh a year for all costs [S2]
A30: Store, procurement and accounts assistant | B30: Rs lakh | C30: 1.44 | D30: 1.8 | E30: One full-time assistant; vegetables need extra grading help
A31: Office, travel, AGM and filing | B31: Rs lakh | C31: 0.9 | D31: 0.9
A32: Fee to federation for accounts, compliance and market desk | B32: Rs lakh | C32: 1.2 | D32: 1.2 | E32: Shared chartered accountant, audit, ROC filings and sales desk; cheaper than each FPO hiring its own
A33: Upkeep and insurance of FPO assets | C33: 0.03 | D33: 0.04 | E33: Share of asset cost per year; solar cold rooms and crates wear faster
A34: Infrastructure per FPO and how it is paid for
A35: Asset kit per FPO | B35: Rs lakh | C35: 10 | D35: 40 | E35: See Infra sheet. Maize stores in leased PACS godowns, so its kit is small
A36: Foundation grant share | C36: 0.6 | D36: 0.4
A37: Government subsidy share | C37: 0 | D37: 0.35 | E37: [S6] MIDH pays 35% of cost for post-harvest units in general areas
A38: FPO own contribution | C38: 0.1 | D38: 0.1 | E38: [S5] AIF requires at least 10% borrower contribution
A39: Loan interest after AIF subvention | C39: 0.06 | D39: 0.06 | E39: [S5] About 9% bank rate less 3% AIF interest subvention
A40: Loan tenure | B40: years | C40: 7 | D40: 7 | E40: [S5] AIF subvention runs up to 7 years
...

Sheet Unit_Econ
A1: Unit economics of one FPO: today versus Year 5 (Rs lakh a year)
A2: Rs lakh a year | B2: Unit | C2: Maize today | D2: Maize Y5 | E2: Veg today | F2: Veg Y5 | G2: How it is worked out
A3: Members | C3: =Case_Data!$C$4 -> 500 | D3: =Case_Data!$C$4+Assumptions!$C$7 -> 650 | E3: =Case_Data!$D$4 -> 500 | F3: =Case_Data!$D$4+Assumptions!$D$7 -> 650
A4: Women share of members | C4: =Case_Data!$C$5 -> 0.2 | D4: =(Case_Data!$C$4*Case_Data!$C$5+Assumptions!$C$7)/D3 -> 0.38461538 | E4: =Case_Data!$D$5 -> 0.2 | F4: =(Case_Data!$D$4*Case_Data!$D$5+Assumptions!$D$7)/F3 -> 0.38461538
A5: Members selling through the FPO | D5: =D3*Assumptions!$C$8 -> 325 | F5: =F3*Assumptions!$D$8 -> 292.5
A6: Produce handled | B6: t | D6: =D5*Assumptions!$C$9*Assumptions!$C$10*Assumptions!$C$11*Assumptions!$C$12 -> 342.225 | F6: =F5*Assumptions!$D$9*Assumptions!$D$10*Assumptions!$D$11*Assumptions!$D$12 -> 559.40625 | G6: Sellers x area x yield x share sold x FPO share
A7: Produce sales | D7: =D6*Assumptions!$C$13/100000 -> 77.000625 | F7: =F6*Assumptions!$D$13/100000 -> 78.316875
A8: Input sales | D8: =D3*Assumptions!$C$14*Assumptions!$C$15*Assumptions!$C$16/100000 -> 27.3 | F8: =F3*Assumptions!$D$14*Assumptions!$D$15*Assumptions!$D$16/100000 -> 18.2
A9: Nursery sales | D9: =Assumptions!$C$17 -> 0 | F9: =Assumptions!$D$17 -> 5
A10: Turnover | C10: =Case_Data!$C$8 -> 27.5 | D10: =SUM(D7:D9) -> 104.30062 | E10: =Case_Data!$D$8 -> 27.5 | F10: =SUM(F7:F9) -> 101.51687 | G10: Today = case midpoint
A12: Margin on produce | D12: =D7*Assumptions!$C$19 -> 2.3100187 | F12: =F7*Assumptions!$D$19 -> 5.4821813
A13: Net gain on stored maize | D13: =D7*Assumptions!$C$20*Assumptions!$C$21 -> 1.23201 | F13: 0
A14: Margin on inputs | D14: =D8*Assumptions!$C$22 -> 2.184 | F14: =F8*Assumptions!$D$22 -> 1.82
A15: Margin on nursery | D15: 0 | F15: =F9*Assumptions!$D$23 -> 1.5
A16: Service fees (drying, storage, cold room) | D16: =D6*(1+Assumptions!$C$25)*Assumptions!$C$24/100000 -> 2.05335 | F16: =Assumptions!$D$26 -> 0.6
A17: Income the FPO keeps | C17: =Case_Data!$C$8*Assumptions!$C$27 -> 1.375 | D17: =SUM(D12:D16) -> 7.7793788 | E17: =Case_Data!$D$8*Assumptions!$D$27 -> 1.375 | F17: =SUM(F12:F16) -> 9.4021812
A19: CEO | C19: =Assumptions!$C$29 -> 3.6 | D19: =Assumptions!$C$29 -> 3.6 | E19: =Assumptions!$D$29 -> 3.6 | F19: =Assumptions!$D$29 -> 3.6
A20: Assistant | C20: =Assumptions!$C$30 -> 1.44 | D20: =Assumptions!$C$30 -> 1.44 | E20: =Assumptions!$D$30 -> 1.8 | F20: =Assumptions!$D$30 -> 1.8
A21: Office, travel, AGM, filing | C21: =Assumptions!$C$31 -> 0.9 | D21: =Assumptions!$C$31 -> 0.9 | E21: =Assumptions!$D$31 -> 0.9 | F21: =Assumptions!$D$31 -> 0.9
A22: Federation fee | C22: 0 | D22: =Assumptions!$C$32 -> 1.2 | E22: 0 | F22: =Assumptions!$D$32 -> 1.2
A23: Asset upkeep and insurance | C23: 0 | D23: =Assumptions!$C$35*Assumptions!$C$33 -> 0.3 | E23: 0 | F23: =Assumptions!$D$35*Assumptions!$D$33 -> 1.6
A24: Loan repayment (principal and interest) | C24: 0 | D24: =Infra!$C$17 -> 0.53740505 | E24: 0 | F24: =Infra!$D$17 -> 1.0748101
A25: Full running cost without any grant | C25: =SUM(C19:C24) -> 5.94 | D25: =SUM(D19:D24) -> 7.9774051 | E25: =SUM(E19:E24) -> 6.3 | F25: =SUM(F19:F24) -> 10.17481
A26: Share of running cost the FPO covers itself | C26: =C17/C25 -> 0.23148148 | D26: =D17/D25 -> 0.9751766 | E26: =E17/E25 -> 0.21825397 | F26: =F17/F25 -> 0.92406454 | G26: Exit test: at least 100% for two years in a row
A27: Surplus (deficit) | C27: =C17-C25 -> -4.565 | D27: =D17-D25 -> -0.1980263 | E27: =E17-E25 -> -4.925 | F27: =F17-F25 -> -0.77262886
A28: Turnover needed to break even at Year 5 margins | D28: =D25/(D17/D10) -> 106.95563 | F28: =F25/(F17/F10) -> 109.85907 | G28: Running cost / income per rupee of turnover
A29: Year 5 turnover as a multiple of today | D29: =D10/C10 -> 3.79275 | F29: =F10/E10 -> 3.6915227

Sheet Working_Capital
A1: Working capital in Year 5 (Rs lakh)
A2: Rs lakh | B2: Unit | C2: Maize FPO | D2: Veg FPO | E2: All 12 | F2: Basis
A3: Peak cash tied up in produce buying | C3: =Unit_Econ!$D$7*Assumptions!$C$42 -> 34.650281 | D3: =Unit_Econ!$F$7*Assumptions!$D$42 -> 15.663375 | E3: =C3*Case_Data!$C$3+D3*Case_Data!$D$3 -> 320.86884 | F3: Stored maize is financed separately by e-NWR pledge loans [S7]
A4: Input credit to members | C4: =Unit_Econ!$D$8*Assumptions!$C$43 -> 8.19 | D4: =Unit_Econ!$F$8*Assumptions!$D$43 -> 5.46 | E4: =C4*Case_Data!$C$3+D4*Case_Data!$D$3 -> 84.63
A5: Peak need | C5: =C3+C4 -> 42.840281 | D5: =D3+D4 -> 21.123375 | E5: =E3+E4 -> 405.49884
A6: Members' share capital | C6: =Unit_Econ!$D$3*Case_Data!$C$9/100000 -> 13 | D6: =Unit_Econ!$F$3*Case_Data!$D$9/100000 -> 13 | E6: =C6*Case_Data!$C$3+D6*Case_Data!$D$3 -> 156
A7: Govt matching equity grant (claim it) | C7: =MIN(Unit_Econ!$D$3*Assumptions!$C$44/100000,Assumptions!$C$45) -> 13 | D7: =MIN(Unit_Econ!$F$3*Assumptions!$D$44/100000,Assumptions!$D$45) -> 13 | E7: =C7*Case_Data!$C$3+D7*Case_Data!$D$3 -> 156 | F7: [S2] Free money most FPOs leave unclaimed; needs clean share register
A8: Less own share of asset kit | C8: =-Infra!$C$15 -> -1 | D8: =-Infra!$D$15 -> -4 | E8: =C8*Case_Data!$C$3+D8*Case_Data!$D$3 -> -27
A9: Own funds for working capital | C9: =SUM(C6:C8) -> 25 | D9: =SUM(D6:D8) -> 22 | E9: =SUM(E6:E8) -> 285
A10: Gap to finance | C10: =MAX(0,C5-C9) -> 17.840281 | D10: =MAX(0,D5-D9) -> 0 | E10: =MAX(0,E5-E9) -> 120.49884
A11: From federation revolving fund | C11: =C10*Assumptions!$C$46 -> 10.704169 | D11: =D10*Assumptions!$C$46 -> 0 | E11: =E10*Assumptions!$C$46 -> 72.299306
A12: From banks / NBFCs | C12: =C10-C11 -> 7.1361125 | D12: =D10-D11 -> 0 | E12: =E10-E11 -> 48.199537
A13: For comparison: gap today, all 12 | E13: =Case_Data!$C$13*Case_Data!$C$3+Case_Data!$D$13*Case_Data!$D$3 -> 180

Sheet Infra
A1: Infrastructure kit per FPO and funding stack (Rs lakh)
A2: Rs lakh | B2: Unit | C2: Maize | D2: Vegetable | F2: Basis
A3: Kit
A4: Drying yard, tarpaulins, moisture meter, scale, sampling kit | C4: 4 | D4: 0 | F4: Meets ethanol and feed-mill moisture specs (14% or lower)
A5: Mobile maize dryer share and cleaner/grader | C5: 5 | D5: 0 | F5: One mobile dryer shared by two FPOs
A6: PACS godown upgrade to WDRA standard (raised stacking, fumigation, fire kit) | C6: 1 | D6: 0 | F6: [S16] Lease idle PACS godowns (Bihar built 6,158 with 16.9 lakh t) instead of building new
A7: Two 5 t solar cold rooms | C7: 0 | D7: 18 | F7: [S8] Ecozen-type units; pay-per-crate service model
A8: Pack shed with grading tables on raised plinth | C8: 0 | D8: 8 | F8: Built above the local high-flood level
A9: Three village collection points and 2,000 crates | C9: 0 | D9: 8 | F9: Crates cut handling loss
A10: Shade-net nursery | C10: 0 | D10: 6 | F10: Seedlings for replanting after floods; sold to members
A11: Total kit | C11: =SUM(C4:C10) -> 10 | D11: =SUM(D4:D10) -> 40
A12: Who pays
A13: Foundation grant | C13: =C11*Assumptions!$C$36 -> 6 | D13: =D11*Assumptions!$D$36 -> 16
A14: Government subsidy (MIDH) | C14: =C11*Assumptions!$C$37 -> 0 | D14: =D11*Assumptions!$D$37 -> 14
A15: FPO own funds | C15: =C11*Assumptions!$C$38 -> 1 | D15: =D11*Assumptions!$D$38 -> 4
A16: AIF bank loan | C16: =C11-C13-C14-C15 -> 3 | D16: =D11-D13-D14-D15 -> 6
A17: Yearly loan repayment | C17: =PMT(Assumptions!$C$39,Assumptions!$C$40,-C16) -> 0.53740505 | D17: =PMT(Assumptions!$D$39,Assumptions!$D$40,-D16) -> 1.0748101 | F17: Annuity at the AIF rate
A18: Programme totals
A19: Foundation grant, all 12 FPOs | C19: =C13*Case_Data!$C$3+D13*Case_Data!$D$3 -> 122
A20: Total asset value, all 12 FPOs | C20: =C11*Case_Data!$C$3+D11*Case_Data!$D$3 -> 270
A21: Asset value per rupee of Foundation grant | C21: =C20/C19 -> 2.2131148

Sheet Federation
A1: Kosi FPO federation in Year 5: running cost and income once grants end (Rs lakh a year)
A2: Rs lakh a year | B2: Unit | C2: Value | D2: Basis
A3: Member FPOs (cohort 1 + cohort 2) | C3: 36
A4: Cohort 2 business as a share of cohort 1 in Year 5 | C4: 1.2 | D4: 24 FPOs at 60% of a cohort 1 FPO each (they join later: 6 in Y1, 18 in Y3)
A5: Federation CEO | C5: 9
A6: Market desk (2 sales managers) | C6: 12
A7: Accounts and compliance (CA on retainer + 2 accountants) | C7: 9
A8: Office, software, travel, audit | C8: 5
A9: Extra servicing cost per FPO beyond 12 | C9: =0.4*(C3-12) -> 9.6 | D9: Rs 0.4 lakh per extra FPO
A10: Running cost | C10: =SUM(C5:C9) -> 44.6
A11: Fees from member FPOs | C11: =Assumptions!$C$32*C3 -> 43.2 | D11: Rs 1.2 lakh per FPO, already inside each FPO's running cost
A12: Share of maize sold through federation contracts | C12: 0.7
A13: Federation commission on that maize | C13: 0.01 | D13: Earned from better price on 1,000 t+ lots
A14: Maize commission income | C14: =Unit_Econ!$D$7*Case_Data!$C$3*(1+C4)*C12*C13 -> 8.3006674
A15: Bulk input buying margin | C15: 0.015 | D15: Federation buys seed and fertiliser in bulk for all FPOs
A16: Input buying income | C16: =(Unit_Econ!$D$8*Case_Data!$C$3+Unit_Econ!$F$8*Case_Data!$D$3)*(1+C4)*C15 -> 9.3093
A17: Average amount lent out by the revolving fund | C17: =Working_Capital!$E$11*(1+C4) -> 159.05847 | D17: Fund share of the working capital gap of both cohorts
A18: Revolving fund capital (incl. flood window) | C18: =Budget!$H$7+Budget!$H$9 -> 250 | D18: From Budget sheet
A19: Share of fund lent out on average | C19: =C17/C18 -> 0.6362339 | D19: Below 100% on purpose: the flood window is kept liquid
A20: Lending rate to FPOs | C20: 0.1 | D20: [S4] Below the 14% to 15% NBFC rate for FPO loans
A21: Loan loss and running cost of the fund | C21: 0.04 | D21: Prudent: 3% loss + 1% admin
A22: Net interest income | C22: =C17*(C20-C21) -> 9.5435084
A23: Income | C23: =C11+C14+C16+C22 -> 70.353476
A24: Share of running cost covered | C24: =C23/C10 -> 1.5774322

Sheet Budget
A1: Indicative budget: US$1 million a year (Rs lakh)
A2: Rs lakh | C2: Y1 26-27 | D2: Y2 27-28 | E2: Y3 28-29 | F2: Y4 29-30 | G2: Y5 30-31 | H2: 5-yr total | I2: What it pays for and why it changes
A3: Intervention 1: Sell together (market access)
A4: Market desk, buyer onboarding, quality testing, certification | C4: 120 | D4: 120 | E4: 100 | F4: 70 | G4: 40 | H4: =SUM(C4:G4) -> 450 | I4: Desk moves onto the federation payroll from Year 4, paid by its commission
A5: Women procurement agents (2 per FPO) start-up stipend | C5: 12 | D5: 12 | E5: 8 | F5: 4 | G5: 0 | H5: =SUM(C5:G5) -> 36 | I5: Paid by FPO commission from Year 3; 24 women earn on volume
A6: Intervention 2: Fund the season (finance)
A7: Revolving fund capital (owned by the federation) | C7: 100 | D7: 50 | E7: 50 | F7: 0 | G7: 0 | H7: =SUM(C7:G7) -> 200 | I7: Sized to the gap left after the govt matching equity grant; lent and repaid, never spent
A8: First-loss deposit with partner bank | C8: 50 | D8: 0 | E8: 0 | F8: 0 | G8: 0 | H8: =SUM(C8:G8) -> 50 | I8: Unlocks bank lines; returns to the federation if unused
A9: Flood contingency window in the fund | C9: 0 | D9: 50 | E9: 0 | F9: 0 | G9: 0 | H9: =SUM(C9:G9) -> 50 | I9: Emergency loans after a flood; kept liquid
A10: Intervention 3: Store and grade (infrastructure)
A11: Asset kits co-funded with AIF and MIDH | C11: =Infra!$C$19*0.6 -> 73.2 | D11: =Infra!$C$19*0.4 -> 48.8 | E11: 0 | F11: 0 | G11: 0 | H11: =SUM(C11:G11) -> 122 | I11: From Infra sheet: 60% in Year 1, 40% in Year 2
A12: Cross-cutting: run it professionally, include women, plan for floods
A13: CEO and assistant salary support (tapering) | C13: =12*5.4*0.8 -> 51.84 | D13: =12*5.4*0.6 -> 38.88 | E13: =12*5.4*0.4 -> 25.92 | F13: =12*5.4*0.2 -> 12.96 | G13: 0 | H13: =SUM(C13:G13) -> 129.6 | I13: 80%, 60%, 40%, 20%, 0% of salary; FPO margin takes over
A14: Accounting software, compliance clean-up, board training | C14: 30 | D14: 25 | E14: 15 | F14: 10 | G14: 5 | H14: =SUM(C14:G14) -> 85 | I14: Front-loaded: one-time clean-up of share registers and filings
A15: Women membership drive, leadership fellowship, creche at centres | C15: 50 | D15: 50 | E15: 45 | F15: 40 | G15: 30 | H15: =SUM(C15:G15) -> 215 | I15: 150 new women members per FPO via SHGs; fellows stand for board seats
A16: Climate: flood alerts, resilient seed trials, BRFSY claims help | C16: 40 | D16: 40 | E16: 35 | F16: 30 | G16: 25 | H16: =SUM(C16:G16) -> 170 | I16: Bihar left PMFBY; farmers must be helped to claim state aid [S17]
A17: KAP support, federation and learning
A18: KAP field team (business, finance, gender, climate leads) | C18: 150 | D18: 160 | E18: 130 | F18: 90 | G18: 50 | H18: =SUM(C18:G18) -> 580 | I18: Peaks while KAP still has the govt CBBO fee, then shrinks as the federation takes over
A19: Federation set-up and staff (tapering) | C19: 25 | D19: 40 | E19: 35 | F19: 20 | G19: 0 | H19: =SUM(C19:G19) -> 120 | I19: Foundation pays most of the running cost in Years 2 and 3; federation pays itself by Year 5
A20: Independent evaluation and audit | C20: 20 | D20: 15 | E20: 25 | F20: 15 | G20: 25 | H20: =SUM(C20:G20) -> 100 | I20: Baseline, mid-term at the Year 2 checkpoint, endline
A21: Second cohort: 6 Kosi FPOs already without govt support from Year 1; 18 more from Year 3 only if the Year 2 checkpoint is met
A22: Playbook, kits, salary taper, fund access for cohort 2 | C22: =950-SUM(C4:C20) -> 227.96 | D22: =950-SUM(D4:D20) -> 300.32 | E22: =950-SUM(E4:E20) -> 481.08 | F22: =950-SUM(F4:F20) -> 658.04 | G22: =950-SUM(G4:G20) -> 775 | H22: =SUM(C22:G22) -> 2442.4 | I22: What is left after cohort 1 is fully funded; see cost per FPO-year below
A23: Total | C23: =SUM(C4:C22) -> 950 | D23: =SUM(D4:D22) -> 950 | E23: =SUM(E4:E22) -> 950 | F23: =SUM(F4:F22) -> 950 | G23: =SUM(G4:G22) -> 950 | H23: =SUM(H4:H22) -> 4750
A24: Total in USD m | C24: =C23*100000/Assumptions!$C$4/1000000 -> 1 | D24: =D23*100000/Assumptions!$C$4/1000000 -> 1 | E24: =E23*100000/Assumptions!$C$4/1000000 -> 1 | F24: =F23*100000/Assumptions!$C$4/1000000 -> 1 | G24: =G23*100000/Assumptions!$C$4/1000000 -> 1 | H24: =H23*100000/Assumptions!$C$4/1000000 -> 5
A26: Shares of the 5-year total
A27: Sell together | H27: =(H4+H5)/H23 -> 0.10231579
A28: Fund the season (capital that stays) | H28: =(H7+H8+H9)/H23 -> 0.063157895
A29: Store and grade | H29: =(H11)/H23 -> 0.025684211
A30: People, women, climate | H30: =(H13+H14+H15+H16)/H23 -> 0.12623158
A31: KAP, federation, evaluation | H31: =(H18+H19+H20)/H23 -> 0.16842105
A32: Second cohort | H32: =(H22)/H23 -> 0.51418947
A34: Value for money
A35: Cohort 1 cost per FPO per year | H35: =(H23-H22)/12/5 -> 38.46 | I35: Includes capital that stays (fund, assets)
A36: Cohort 2 FPO-years supported | H36: =6*5+18*3 -> 84
A37: Cohort 2 cost per FPO per year | H37: =H22/H36 -> 29.07619 | I37: About 75% of cohort 1: desk, fund and federation already exist. Govt pays a CBBO Rs 5 lakh per FPO a year [S2]
A38: Farmer members reached in Year 5 (both cohorts) | H38: =Federation!$C$3*Unit_Econ!$D$3 -> 23400
A39: Cost per farmer member over 5 years | B39: Rs | H39: =H23*100000/H38 -> 20299.145

Sheet Targets
A1: Targets at end of Year 5 versus what similar programmes achieved
A2: Measure | B2: Unit | C2: Today | D2: Year 5 target | E2: Benchmark | F2: Benchmark source
A3: Members selling through FPO (maize / veg avg) | C3: 0.15 | D3: =(Assumptions!$C$8*7+Assumptions!$D$8*5)/12 -> 0.47916667 | E3: 0.39 | F3: [S9] SRIJAN: 39% after 2 years. Today: our estimate (case: weak engagement)
A4: Average turnover per FPO | B4: Rs lakh | C4: =Case_Data!$C$8 -> 27.5 | D4: =(Unit_Econ!$D$10*7+Unit_Econ!$F$10*5)/12 -> 103.14073 | E4: 100 | F4: [S3] 1,135 of 8,961 scheme FPOs (12.7%) crossed Rs 1 crore in FY25
A5: FPOs covering 100% of running cost | C5: 0 | D5: 6 | E5: 4 | F5: [S1] About one third of FPOs viable (ICAR-NIAP), i.e. 4 of 12. Target 6 of 12, and all 12 above 85%
A6: Women share of members | C6: =Case_Data!$C$5 -> 0.2 | D6: =Unit_Econ!$D$4 -> 0.38461538
A7: Women directors per board | C7: 1 | D7: 3 | F7: [S10] FPOs with female or mixed leadership survive past support 4 to 13 points more often
A8: FPOs with a bank or NBFC credit line | C8: 0 | D8: 12 | E8: 0.3 | F8: [S4] Only 30% of FPOs got bank loans; those with credit: 61% profitable without support vs 43%
A9: Federation covers its own running cost | C9: 0 | D9: 1 | F9: 1 = yes

Sheet Checks
A1: Integrity checks (all should read OK)
A2: Budget each year equals Rs 950 lakh (USD 1m at Rs 95) | C2: =ABS(Budget!$C$23-950)+ABS(Budget!$D$23-950)+ABS(Budget!$E$23-950)+ABS(Budget!$F$23-950)+ABS(Budget!$G$23-950) -> 0 | D2: =IF(ABS(C2)<0.001,"OK","CHECK") -> OK
A3: Budget shares add to 100% | C3: =Budget!$H$27+Budget!$H$28+Budget!$H$29+Budget!$H$30+Budget!$H$31+Budget!$H$32-1 -> 0 | D3: =IF(ABS(C3)<0.001,"OK","CHECK") -> OK
A4: Infra funding stack adds to kit cost | C4: =ABS(Infra!$C$13+Infra!$C$14+Infra!$C$15+Infra!$C$16-Infra!$C$11)+ABS(Infra!$D$13+Infra!$D$14+Infra!$D$15+Infra!$D$16-Infra!$D$11) -> 0 | D4: =IF(ABS(C4)<0.001,"OK","CHECK") -> OK
A5: Infra in budget equals Infra sheet | C5: =Budget!$H$11-Infra!$C$19 -> 0 | D5: =IF(ABS(C5)<0.001,"OK","CHECK") -> OK
A6: Case: share capital equals working capital available | C6: =Case_Data!$C$10-Case_Data!$C$11 -> 0 | D6: =IF(ABS(C6)<0.001,"OK","CHECK") -> OK
A7: Working capital sources add to gap | C7: =Working_Capital!$E$11+Working_Capital!$E$12-Working_Capital!$E$10 -> 0 | D7: =IF(ABS(C7)<0.001,"OK","CHECK") -> OK
A8: Fund capital covers what is lent out (0 if yes) | C8: =MAX(0,Federation!$C$17-Federation!$C$18) -> 0 | D8: =IF(ABS(C8)<0.001,"OK","CHECK") -> OK
A9: Federation covers its running cost (0 if yes) | C9: =MAX(0,1-Federation!$C$24) -> 0 | D9: =IF(ABS(C9)<0.001,"OK","CHECK") -> OK
